Workbook

Sheet urbanthreads_q4
A1: Order ID | B1: Order Date | C1: Customer ID | D1: Type | E1: SKU | F1: Category | G1: Product Name | H1: Unit Price | I1: Unit_price_flag | J1: Qty | K1: Quantity_Flag | L1: Total | M1: order_total | N1: Total_check | O1: Discount Code | P1: Disc % | Q1: Disc_per_status | R1: Payment | S1: Source | T1: City | U1: State | V1: Warehouse | W1: Del Date | X1: delivery_order before order_date | Y1: Status | Z1: Cancelled_Delivery_Check | AA1: Return? | AB1: Reason | AC1: Return_Reason_Check | AD1: Ret Rec | AE1: return_received_date vs delivery_date | AF1: Refund
A2: UT-100002 | B2: 45566 | C2: CUST_10002 | D2: Returning | E2: DRSFRMS | F2: Dresses | G2: Floral Midi Dress | H2: 2499 | I2: =IF(OR(H2<=0,H2>50000),"Outlier","Normal") -> Normal | J2: 1 | K2: =IF(J2>10,"Outlier","Normal") -> Normal | L2: 2499 | M2: =H2*J2*(1-(P2/100)) -> 1999.2 | N2: =IF(ABS(L2-M2)<1,"Match","Mismatch") -> Mismatch | O2: DIWALI20 | P2: 20 | Q2: =IF(OR(P2<0,C2>100),"Invalid","valid") -> Invalid | R2: Credit Card | S2: Mobile App | T2: Delhi | U2: Delhi | V2: Delhi | W2: 45569 | X2: =IF(AND(B2<>"",W2<>""),IF(B2<D2,"Invalid","Valid"),"Not applicable") -> Invalid | Y2: Delivered | Z2: =IF(AND(Y2="Cancelled",W2<>""),"Invalid","Valid") -> Valid | AA2: Yes | AB2: Size Issue | AC2: =IF(AA2="Yes", IF(OR(AB2="", AB2="Not Applicable"), "Missing Reason", "Valid"), "Not Applicable") -> Valid | AD2: 45580 | AE2: =IF(AND(W2<>"",AD2<>""),IF(W2<AD2,"Invalid","Valid"),"Not Applicable") -> Invalid | AF2: Processed
A3: UT-100006 | B3: 45567 | C3: CUST_10005 | D3: Returning | E3: TOPFRMS | F3: Tops | G3: Printed Blouse | H3: 1599 | I3: =IF(OR(H3<=0,H3>50000),"Outlier","Normal") -> Normal | J3: 2 | K3: =IF(J3>10,"Outlier","Normal") -> Normal | L3: 3198 | M3: =H3*J3*(1-(P3/100)) -> 3198 | N3: =IF(ABS(L3-M3)<1,"Match","Mismatch") -> Match | O3: No code | P3: 0 | Q3: =IF(OR(P3<0,C3>100),"Invalid","valid") -> Invalid | R3: Credit Card | S3: Mobile App | T3: Hyderabad | U3: Telangana | V3: Bangalore | W3: 45572 | X3: =IF(AND(B3<>"",W3<>""),IF(B3<D3,"Invalid","Valid"),"Not applicable") -> Invalid | Y3: Delivered | Z3: =IF(AND(Y3="Cancelled",W3<>""),"Invalid","Valid") -> Valid | AA3: Yes | AB3: Changed Mind | AC3: =IF(AA3="Yes", IF(OR(AB3="", AB3="Not Applicable"), "Missing Reason", "Valid"), "Not Applicable") -> Valid | AD3: 45583 | AE3: =IF(AND(W3<>"",AD3<>""),IF(W3<AD3,"Invalid","Valid"),"Not Applicable") -> Invalid | AF3: Processed
A4: UT-100004 | B4: 45566 | C4: CUST_10004 | D4: New | E4: OUTJKTXL | F4: Outerwear | G4: Denim Jacket | H4: 3499 | I4: =IF(OR(H4<=0,H4>50000),"Outlier","Normal") -> Normal | J4: 1 | K4: =IF(J4>10,"Outlier","Normal") -> Normal | L4: 3499 | M4: =H4*J4*(1-(P4/100)) -> 2974.15 | N4: =IF(ABS(L4-M4)<1,"Match","Mismatch") -> Mismatch | O4: FIRST15 | P4: 15 | Q4: =IF(OR(P4<0,C4>100),"Invalid","valid") -> Invalid | R4: Debit Card | S4: Instagram Shop | T4: Chennai | U4: Tamil Nadu | V4: Mumbai | W4: 45573 | X4: =IF(AND(B4<>"",W4<>""),IF(B4<D4,"Invalid","Valid"),"Not applicable") -> Invalid | Y4: Delivered | Z4: =IF(AND(Y4="Cancelled",W4<>""),"Invalid","Valid") -> Valid | AA4: Yes | AB4: Quality Defect | AC4: =IF(AA4="Yes", IF(OR(AB4="", AB4="Not Applicable"), "Missing Reason", "Valid"), "Not Applicable") -> Valid | AD4: 45585 | AE4: =IF(AND(W4<>"",AD4<>""),IF(W4<AD4,"Invalid","Valid"),"Not Applicable") -> Invalid | AF4: Processed
A5: UT-100009 | B5: 45567 | C5: CUST_10008 | D5: Returning | E5: TOPCASXL | F5: Tops | G5: Oversized Tee | H5: 1399 | I5: =IF(OR(H5<=0,H5>50000),"Outlier","Normal") -> Normal | J5: 5 | K5: =IF(J5>10,"Outlier","Normal") -> Normal | L5: 6995 | M5: =H5*J5*(1-(P5/100)) -> 6995 | N5: =IF(ABS(L5-M5)<1,"Match","Mismatch") -> Match | O5: No code | P5: 0 | Q5: =IF(OR(P5<0,C5>100),"Invalid","valid") -> Invalid | R5: Credit Card | S5: Website | T5: Ahmedabad | U5: Gujarat | V5: Mumbai | W5: 45574 | X5: =IF(AND(B5<>"",W5<>""),IF(B5<D5,"Invalid","Valid"),"Not applicable") -> Invalid | Y5: Delivered | Z5: =IF(AND(Y5="Cancelled",W5<>""),"Invalid","Valid") -> Valid | AA5: Yes | AB5: Size Issue | AC5: =IF(AA5="Yes", IF(OR(AB5="", AB5="Not Applicable"), "Missing Reason", "Valid"), "Not Applicable") -> Valid | AD5: 45587 | AE5: =IF(AND(W5<>"",AD5<>""),IF(W5<AD5,"Invalid","Valid"),"Not Applicable") -> Invalid | AF5: Processed
A6: UT-100010 | B6: 45567 | C6: CUST_10009 | D6: New | E6: OUTBLZM | F6: Outerwear | G6: Casual Blazer | H6: 4999 | I6: =IF(OR(H6<=0,H6>50000),"Outlier","Normal") -> Normal | J6: -1 | K6: =IF(J6>10,"Outlier","Normal") -> Normal | L6: 4999 | M6: =H6*J6*(1-(P6/100)) -> -4999 | N6: =IF(ABS(L6-M6)<1,"Match","Mismatch") -> Mismatch | O6: No code | P6: 0 | Q6: =IF(OR(P6<0,C6>100),"Invalid","valid") -> Invalid | R6: Debit Card | S6: Instagram Shop | T6: Jaipur | U6: Rajasthan | V6: Delhi | W6: 45576 | X6: =IF(AND(B6<>"",W6<>""),IF(B6<D6,"Invalid","Valid"),"Not applicable") -> Invalid | Y6: Delivered | Z6: =IF(AND(Y6="Cancelled",W6<>""),"Invalid","Valid") -> Valid | AA6: Yes | AB6: Wrong Item | AC6: =IF(AA6="Yes", IF(OR(AB6="", AB6="Not Applicable"), "Missing Reason", "Valid"), "Not Applicable") -> Valid | AD6: 45590 | AE6: =IF(AND(W6<>"",AD6<>""),IF(W6<AD6,"Invalid","Valid"),"Not Applicable") -> Invalid | AF6: Pending
A7: UT-100016 | B7: 45569 | C7: CUST_10015 | D7: Returning | E7: ACCJWLOS | F7: Accessories | G7: Statement Earrings | H7: 599 | I7: =IF(OR(H7<=0,H7>50000),"Outlier","Normal") -> Normal | J7: 4 | K7: =IF(J7>10,"Outlier","Normal") -> Normal | L7: 2396 | M7: =H7*J7*(1-(P7/100)) -> 2396 | N7: =IF(ABS(L7-M7)<1,"Match","Mismatch") -> Match | O7: No code | P7: 0 | Q7: =IF(OR(P7<0,C7>100),"Invalid","valid") -> Invalid | R7: COD | S7: Website | T7: Noida | U7: Uttar Pradesh | V7: Delhi | W7: 45579 | X7: =IF(AND(B7<>"",W7<>""),IF(B7<D7,"Invalid","Valid"),"Not applicable") -> Invalid | Y7: Delivered | Z7: =IF(AND(Y7="Cancelled",W7<>""),"Invalid","Valid") -> Valid | AA7: Yes | AB7: Damaged in Transit | AC7: =IF(AA7="Yes", IF(OR(AB7="", AB7="Not Applicable"), "Missing Reason", "Valid"), "Not Applicable") -> Valid | AD7: 45591 | AE7: =IF(AND(W7<>"",AD7<>""),IF(W7<AD7,"Invalid","Valid"),"Not Applicable") -> Invalid | AF7: Processed
A8: UT-100014 | B8: 45568 | C8: CUST_10013 | D8: New | E8: BOTSKTS | F8: Bottoms | G8: Pleated Skirt | H8: 1799 | I8: =IF(OR(H8<=0,H8>50000),"Outlier","Normal") -> Normal | J8: 2 | K8: =IF(J8>10,"Outlier","Normal") -> Normal | L8: 3598 | M8: =H8*J8*(1-(P8/100)) -> 2878.4 | N8: =IF(ABS(L8-M8)<1,"Match","Mismatch") -> Mismatch | O8: DIWALI20 | P8: 20 | Q8: =IF(OR(P8<0,C8>100),"Invalid","valid") -> Invalid | R8: UPI | S8: Instagram Shop | T8: Delhi | U8: Delhi | V8: Delhi | W8: 45576 | X8: =IF(AND(B8<>"",W8<>""),IF(B8<D8,"Invalid","Valid"),"Not applicable") -> Invalid | Y8: Delivered | Z8: =IF(AND(Y8="Cancelled",W8<>""),"Invalid","Valid") -> Valid | AA8: Yes | AB8: Size Issue | AC8: =IF(AA8="Yes", IF(OR(AB8="", AB8="Not Applicable"), "Missing Reason", "Valid"), "Not Applicable") -> Valid | AD8: 45593 | AE8: =IF(AND(W8<>"",AD8<>""),IF(W8<AD8,"Invalid","Valid"),"Not Applicable") -> Invalid | AF8: Processed
A9: UT-100019 | B9: 45569 | C9: CUST_10018 | D9: Returning | E9: BOTJGRM | F9: Bottoms | G9: Joggers | H9: 1499 | I9: =IF(OR(H9<=0,H9>50000),"Outlier","Normal") -> Normal | J9: 2 | K9: =IF(J9>10,"Outlier","Normal") -> Normal | L9: 2998 | M9: =H9*J9*(1-(P9/100)) -> 2998 | N9: =IF(ABS(L9-M9)<1,"Match","Mismatch") -> Match | O9: No code | P9: 0 | Q9: =IF(OR(P9<0,C9>100),"Invalid","valid") -> Invalid | R9: Wallet | S9: Instagram Shop | T9: Surat | U9: Gujarat | V9: Mumbai | W9: 45578 | X9: =IF(AND(B9<>"",W9<>""),IF(B9<D9,"Invalid","Valid"),"Not applicable") -> Invalid | Y9: Delivered | Z9: =IF(AND(Y9="Cancelled",W9<>""),"Invalid","Valid") -> Valid | AA9: Yes | AB9: Size Issue | AC9: =IF(AA9="Yes", IF(OR(AB9="", AB9="Not Applicable"), "Missing Reason", "Valid"), "Not Applicable") -> Valid | AD9: 45595 | AE9: =IF(AND(W9<>"",AD9<>""),IF(W9<AD9,"Invalid","Valid"),"Not Applicable") -> Invalid | AF9: Processed
A10: UT-100022 | B10: 45570 | C10: CUST_10021 | D10: Returning | E10: DRSSHTXS | F10: Dresses | G10: Shirt Dress | H10: 2399 | I10: =IF(OR(H10<=0,H10>50000),"Outlier","Normal") -> Normal | J10: 1 | K10: =IF(J10>10,"Outlier","Normal") -> Normal | L10: 2399 | M10: =H10*J10*(1-(P10/100)) -> 2399 | N10: =IF(ABS(L10-M10)<1,"Match","Mismatch") -> Match | O10: No code | P10: 0 | Q10: =IF(OR(P10<0,C10>100),"Invalid","valid") -> Invalid | R10: Credit Card | S10: Website | T10: Nagpur | U10: Maharashtra | V10: Mumbai | W10: 45581 | X10: =IF(AND(B10<>"",W10<>""),IF(B10<D10,"Invalid","Valid"),"Not applicable") -> Invalid | Y10: Delivered | Z10: =IF(AND(Y10="Cancelled",W10<>""),"Invalid","Valid") -> Valid | AA10: Yes | AB10: Quality Defect | AC10: =IF(AA10="Yes", IF(OR(AB10="", AB10="Not Applicable"), "Missing Reason", "Valid"), "Not Applicable") -> Valid | AD10: 45598 | AE10: =IF(AND(W10<>"",AD10<>""),IF(W10<AD10,"Invalid","Valid"),"Not Applicable") -> Invalid | AF10: Processed
A11: UT-100033 | B11: 45573 | C11: CUST_10032 | D11: New | E11: OUTWOLL | F11: Outerwear | G11: Wool Coat | H11: 6999 | I11: =IF(OR(H11<=0,H11>50000),"Outlier","Normal") -> Normal | J11: 1 | K11: =IF(J11>10,"Outlier","Normal") -> Normal | L11: 6999 | M11: =H11*J11*(1-(P11/100)) -> 5949.15 | N11: =IF(ABS(L11-M11)<1,"Match","Mismatch") -> Mismatch | O11: FIRST15 | P11: 15 | Q11: =IF(OR(P11<0,C11>100),"Invalid","valid") -> Invalid | R11: Debit Card | S11: Instagram Shop | T11: Kolkata | U11: West Bengal | V11: Delhi | W11: 45581 | X11: =IF(AND(B11<>"",W11<>""),IF(B11<D11,"Invalid","Valid"),"Not applicable") -> Invalid | Y11: Delivered | Z11: =IF(AND(Y11="Cancelled",W11<>""),"Invalid","Valid") -> Valid | AA11: Yes | AB11: Quality Defect | AC11: =IF(AA11="Yes", IF(OR(AB11="", AB11="Not Applicable"), "Missing Reason", "Valid"), "Not Applicable") -> Valid | AD11: 45601 | AE11: =IF(AND(W11<>"",AD11<>""),IF(W11<AD11,"Invalid","Valid"),"Not Applicable") -> Invalid | AF11: Processed
A12: UT-100024 | B12: 45571 | C12: CUST_10023 | D12: New | E12: BOTSHTM | F12: Bottoms | G12: Cotton Shorts | H12: 1199 | I12: =IF(OR(H12<=0,H12>50000),"Outlier","Normal") -> Normal | J12: 3 | K12: =IF(J12>10,"Outlier","Normal") -> Normal | L12: 3597 | M12: =H12*J12*(1-(P12/100)) -> 3597 | N12: =IF(ABS(L12-M12)<1,"Match","Mismatch") -> Match | O12: No code | P12: 0 | Q12: =IF(OR(P12<0,C12>100),"Invalid","valid") -> Invalid | R12: COD | S12: Instagram Shop | T12: Kochi | U12: Kerala | V12: Bangalore | W12: 45583 | X12: =IF(AND(B12<>"",W12<>""),IF(B12<D12,"Invalid","Valid"),"Not applicable") -> Invalid | Y12: Delivered | Z12: =IF(AND(Y12="Cancelled",W12<>""),"Invalid","Valid") -> Valid | AA12: Yes | AB12: Changed Mind | AC12: =IF(AA12="Yes", IF(OR(AB12="", AB12="Not Applicable"), "Missing Reason", "Valid"), "Not Applicable") -> Valid | AD12: 45601 | AE12: =IF(AND(W12<>"",AD12<>""),IF(W12<AD12,"Invalid","Valid"),"Not Applicable") -> Invalid | AF12: Processed
A13: UT-100042 | B13: 45575 | C13: CUST_10041 | D13: Returning | E13: TOPOFFM | F13: Tops | G13: Off-Shoulder Top | H13: 1599 | I13: =IF(OR(H13<=0,H13>50000),"Outlier","Normal") -> Normal | J13: 2 | K13: =IF(J13>10,"Outlier","Normal") -> Normal | L13: 3198 | M13: =H13*J13*(1-(P13/100)) -> 2558.4 | N13: =IF(ABS(L13-M13)<1,"Match","Mismatch") -> Mismatch | O13: DIWALI20 | P13: 20 | Q13: =IF(OR(P13<0,C13>100),"Invalid","valid") -> Invalid | R13: Credit Card | S13: Mobile App | T13: Delhi | U13: Delhi | V13: Delhi | W13: 45582 | X13: =IF(AND(B13<>"",W13<>""),IF(B13<D13,"Invalid","Valid"),"Not applicable") -> Invalid | Y13: Delivered | Z13: =IF(AND(Y13="Cancelled",W13<>""),"Invalid","Valid") -> Valid | AA13: Yes | AB13: Wrong Item | AC13: =IF(AA13="Yes", IF(OR(AB13="", AB13="Not Applicable"), "Missing Reason", "Valid"), "Not Applicable") -> Valid | AD13: 45604 | AE13: =IF(AND(W13<>"",AD13<>""),IF(W13<AD13,"Invalid","Valid"),"Not Applicable") -> Invalid | AF13: Processed
... A76: UT-100158 | B76: 45604 | C76: CUST_10157 | D76: Returning | E76: BOTTIES | F76: Bottoms | G76: Tie Dye Pants | H76: 1599 | I76: =IF(OR(H76<=0,H76>50000),"Outlier","Normal") -> Normal | J76: 1 | K76: =IF(J76>10,"Outlier","Normal") -> Normal | L76: 1599 | M76: =H76*J76*(1-(P76/100)) -> 1599 | N76: =IF(ABS(L76-M76)<1,"Match","Mismatch") -> Match | O76: No code | P76: 0 | Q76: =IF(OR(P76<0,C76>100),"Invalid","valid") -> Invalid | R76: Credit Card | S76: Mobile App | T76: Gurgaon | U76: Haryana | V76: Delhi | W76: 45616 | X76: =IF(AND(B76<>"",W76<>""),IF(B76<D76,"Invalid","Valid"),"Not applicable") -> Invalid | Y76: Delivered | Z76: =IF(AND(Y76="Cancelled",W76<>""),"Invalid","Valid") -> Valid | AA76: Yes | AB76: Changed Mind | AC76: =IF(AA76="Yes", IF(OR(AB76="", AB76="Not Applicable"), "Missing Reason", "Valid"), "Not Applicable") -> Valid | AD76: 45644 | AE76: =IF(AND(W76<>"",AD76<>""),IF(W76<AD76,"Invalid","Valid"),"Not Applicable") -> Invalid | AF76: Processed
A77: UT-100156 | B77: 45603 | C77: CUST_10155 | D77: New | E77: TOPAJRM | F77: Tops | G77: Ajrakh Print Top | H77: 1799 | I77: =IF(OR(H77<=0,H77>50000),"Outlier","Normal") -> Normal | J77: 1 | K77: =IF(J77>10,"Outlier","Normal") -> Normal | L77: 1799 | M77: =H77*J77*(1-(P77/100)) -> 1529.15 | N77: =IF(ABS(L77-M77)<1,"Match","Mismatch") -> Mismatch | O77: 42309 | P77: 15 | Q77: =IF(OR(P77<0,C77>100),"Invalid","valid") -> Invalid | R77: UPI | S77: Instagram Shop | T77: Chandigarh | U77: Punjab | V77: Delhi | W77: 45616 | X77: =IF(AND(B77<>"",W77<>""),IF(B77<D77,"Invalid","Valid"),"Not applicable") -> Invalid | Y77: Delivered | Z77: =IF(AND(Y77="Cancelled",W77<>""),"Invalid","Valid") -> Valid | AA77: Yes | AB77: Wrong Item | AC77: =IF(AA77="Yes", IF(OR(AB77="", AB77="Not Applicable"), "Missing Reason", "Valid"), "Not Applicable") -> Valid | AD77: 45645 | AE77: =IF(AND(W77<>"",AD77<>""),IF(W77<AD77,"Invalid","Valid"),"Not Applicable") -> Invalid | AF77: Processed
A78: UT-100160 | B78: 45605 | C78: CUST_10159 | D78: New | E78: ACCHRMOS | F78: Accessories | G78: Hair Clip Set | H78: 499 | I78: =IF(OR(H78<=0,H78>50000),"Outlier","Normal") -> Normal | J78: 3 | K78: =IF(J78>10,"Outlier","Normal") -> Normal | L78: 1497 | M78: =H78*J78*(1-(P78/100)) -> 1497 | N78: =IF(ABS(L78-M78)<1,"Match","Mismatch") -> Match | O78: No code | P78: 0 | Q78: =IF(OR(P78<0,C78>100),"Invalid","valid") -> Invalid | R78: UPI | S78: Website | T78: Surat | U78: Gujarat | V78: Mumbai | W78: 45617 | X78: =IF(AND(B78<>"",W78<>""),IF(B78<D78,"Invalid","Valid"),"Not applicable") -> Invalid | Y78: Delivered | Z78: =IF(AND(Y78="Cancelled",W78<>""),"Invalid","Valid") -> Valid | AA78: Yes | AB78: Damaged in Transit | AC78: =IF(AA78="Yes", IF(OR(AB78="", AB78="Not Applicable"), "Missing Reason", "Valid"), "Not Applicable") -> Valid | AD78: 45645 | AE78: =IF(AND(W78<>"",AD78<>""),IF(W78<AD78,"Invalid","Valid"),"Not Applicable") -> Invalid | AF78: Processed
A79: UT-100154 | B79: 45603 | C79: CUST_10153 | D79: New | E79: OUTJQDL | F79: Outerwear | G79: Jacquard Jacket | H79: 4599 | I79: =IF(OR(H79<=0,H79>50000),"Outlier","Normal") -> Normal | J79: 1 | K79: =IF(J79>10,"Outlier","Normal") -> Normal | L79: 4599 | M79: =H79*J79*(1-(P79/100)) -> 4599 | N79: =IF(ABS(L79-M79)<1,"Match","Mismatch") -> Match | O79: No code | P79: 0 | Q79: =IF(OR(P79<0,C79>100),"Invalid","valid") -> Invalid | R79: Credit Card | S79: Website | T79: Mumbai | U79: Maharashtra | V79: Mumbai | W79: 45617 | X79: =IF(AND(B79<>"",W79<>""),IF(B79<D79,"Invalid","Valid"),"Not applicable") -> Invalid | Y79: Delivered | Z79: =IF(AND(Y79="Cancelled",W79<>""),"Invalid","Valid") -> Valid | AA79: Yes | AB79: Size Issue | AC79: =IF(AA79="Yes", IF(OR(AB79="", AB79="Not Applicable"), "Missing Reason", "Valid"), "Not Applicable") -> Valid | AD79: 45646 | AE79: =IF(AND(W79<>"",AD79<>""),IF(W79<AD79,"Invalid","Valid"),"Not Applicable") -> Invalid | AF79: Processed
A80: UT-100162 | B80: 45605 | C80: CUST_10161 | D80: New | E80: DRSFLRS | F80: Dresses | G80: Floral Print Dress | H80: 2399 | I80: =IF(OR(H80<=0,H80>50000),"Outlier","Normal") -> Normal | J80: 1 | K80: =IF(J80>10,"Outlier","Normal") -> Normal | L80: 2399 | M80: =H80*J80*(1-(P80/100)) -> 2039.15 | N80: =IF(ABS(L80-M80)<1,"Match","Mismatch") -> Mismatch | O80: 42309 | P80: 15 | Q80: =IF(OR(P80<0,C80>100),"Invalid","valid") -> Invalid | R80: Credit Card | S80: Instagram Shop | T80: Bhopal | U80: Madhya Pradesh | V80: Mumbai | W80: 45620 | X80: =IF(AND(B80<>"",W80<>""),IF(B80<D80,"Invalid","Valid"),"Not applicable") -> Invalid | Y80: Delivered | Z80: =IF(AND(Y80="Cancelled",W80<>""),"Invalid","Valid") -> Valid | AA80: Yes | AB80: Size Issue | AC80: =IF(AA80="Yes", IF(OR(AB80="", AB80="Not Applicable"), "Missing Reason", "Valid"), "Not Applicable") -> Valid | AD80: 45648 | AE80: =IF(AND(W80<>"",AD80<>""),IF(W80<AD80,"Invalid","Valid"),"Not Applicable") -> Invalid | AF80: Processed
A81: UT-100166 | B81: 45607 | C81: CUST_10165 | D81: New | E81: TOPSLVS | F81: Tops | G81: Sleeve Detail Top | H81: 1599 | I81: =IF(OR(H81<=0,H81>50000),"Outlier","Normal") -> Normal | J81: 1 | K81: =IF(J81>10,"Outlier","Normal") -> Normal | L81: 1599 | M81: =H81*J81*(1-(P81/100)) -> 1359.15 | N81: =IF(ABS(L81-M81)<1,"Match","Mismatch") -> Mismatch | O81: 42309 | P81: 15 | Q81: =IF(OR(P81<0,C81>100),"Invalid","valid") -> Invalid | R81: Credit Card | S81: Website | T81: Vizag | U81: Andhra Pradesh | V81: Bangalore | W81: 45620 | X81: =IF(AND(B81<>"",W81<>""),IF(B81<D81,"Invalid","Valid"),"Not applicable") -> Invalid | Y81: Delivered | Z81: =IF(AND(Y81="Cancelled",W81<>""),"Invalid","Valid") -> Valid | AA81: Yes | AB81: Size Issue | AC81: =IF(AA81="Yes", IF(OR(AB81="", AB81="Not Applicable"), "Missing Reason", "Valid"), "Not Applicable") -> Valid | AD81: 45649 | AE81: =IF(AND(W81<>"",AD81<>""),IF(W81<AD81,"Invalid","Valid"),"Not Applicable") -> Invalid | AF81: Processed
A82: UT-100164 | B82: 45575 | C82: CUST_10163 | D82: New | E82: OUTSTRL | F82: Outerwear | G82: Striped Blazer | H82: 4199 | I82: =IF(OR(H82<=0,H82>50000),"Outlier","Normal") -> Normal | J82: 1 | K82: =IF(J82>10,"Outlier","Normal") -> Normal | L82: 4199 | M82: =H82*J82*(1-(P82/100)) -> 4199 | N82: =IF(ABS(L82-M82)<1,"Match","Mismatch") -> Match | O82: No code | P82: 0 | Q82: =IF(OR(P82<0,C82>100),"Invalid","valid") -> Invalid | R82: UPI | S82: Mobile App | T82: Coimbatore | U82: Tamil Nadu | V82: Bangalore | W82: 45621 | X82: =IF(AND(B82<>"",W82<>""),IF(B82<D82,"Invalid","Valid"),"Not applicable") -> Invalid | Y82: Delivered | Z82: =IF(AND(Y82="Cancelled",W82<>""),"Invalid","Valid") -> Valid | AA82: Yes | AB82: Quality Defect | AC82: =IF(AA82="Yes", IF(OR(AB82="", AB82="Not Applicable"), "Missing Reason", "Valid"), "Not Applicable") -> Valid | AD82: 45650 | AE82: =IF(AND(W82<>"",AD82<>""),IF(W82<AD82,"Invalid","Valid"),"Not Applicable") -> Invalid | AF82: Processed
A83: UT-100171 | B83: 45608 | C83: CUST_10170 | D83: New | E83: TOPMCRM | F83: Tops | G83: Macrame Top | H83: 1899 | I83: =IF(OR(H83<=0,H83>50000),"Outlier","Normal") -> Normal | J83: 1 | K83: =IF(J83>10,"Outlier","Normal") -> Normal | L83: 1899 | M83: =H83*J83*(1-(P83/100)) -> 1899 | N83: =IF(ABS(L83-M83)<1,"Match","Mismatch") -> Match | O83: No code | P83: 0 | Q83: =IF(OR(P83<0,C83>100),"Invalid","valid") -> Invalid | R83: Debit Card | S83: Instagram Shop | T83: Kanpur | U83: Uttar Pradesh | V83: Delhi | W83: 45622 | X83: =IF(AND(B83<>"",W83<>""),IF(B83<D83,"Invalid","Valid"),"Not applicable") -> Invalid | Y83: Delivered | Z83: =IF(AND(Y83="Cancelled",W83<>""),"Invalid","Valid") -> Valid | AA83: Yes | AB83: Quality Defect | AC83: =IF(AA83="Yes", IF(OR(AB83="", AB83="Not Applicable"), "Missing Reason", "Valid"), "Not Applicable") -> Valid | AD83: 45650 | AE83: =IF(AND(W83<>"",AD83<>""),IF(W83<AD83,"Invalid","Valid"),"Not Applicable") -> Invalid | AF83: Processed
A84: UT-100167 | B84: 45607 | C84: CUST_10166 | D84: New | E84: DRSASYM | F84: Dresses | G84: Asymmetric Dress | H84: 2899 | I84: =IF(OR(H84<=0,H84>50000),"Outlier","Normal") -> Normal | J84: 1 | K84: =IF(J84>10,"Outlier","Normal") -> Normal | L84: 2899 | M84: =H84*J84*(1-(P84/100)) -> 2899 | N84: =IF(ABS(L84-M84)<1,"Match","Mismatch") -> Match | O84: No code | P84: 0 | Q84: =IF(OR(P84<0,C84>100),"Invalid","valid") -> Invalid | R84: COD | S84: Mobile App | T84: Thiruvananthapuram | U84: Kerala | V84: Bangalore | W84: 45622 | X84: =IF(AND(B84<>"",W84<>""),IF(B84<D84,"Invalid","Valid"),"Not applicable") -> Invalid | Y84: Delivered | Z84: =IF(AND(Y84="Cancelled",W84<>""),"Invalid","Valid") -> Valid | AA84: Yes | AB84: Wrong Item | AC84: =IF(AA84="Yes", IF(OR(AB84="", AB84="Not Applicable"), "Missing Reason", "Valid"), "Not Applicable") -> Valid | AD84: 45651 | AE84: =IF(AND(W84<>"",AD84<>""),IF(W84<AD84,"Invalid","Valid"),"Not Applicable") -> Invalid | AF84: Processed
A85: UT-100173 | B85: 45609 | C85: CUST_10172 | D85: Returning | E85: BOTVLTL | F85: Bottoms | G85: Velvet Pants | H85: 2499 | I85: =IF(OR(H85<=0,H85>50000),"Outlier","Normal") -> Normal | J85: 1 | K85: =IF(J85>10,"Outlier","Normal") -> Normal | L85: 2499 | M85: =H85*J85*(1-(P85/100)) -> 2124.15 | N85: =IF(ABS(L85-M85)<1,"Match","Mismatch") -> Mismatch | O85: 42309 | P85: 15 | Q85: =IF(OR(P85<0,C85>100),"Invalid","valid") -> Invalid | R85: Credit Card | S85: Mobile App | T85: Delhi | U85: Delhi | V85: Delhi | W85: 45622 | X85: =IF(AND(B85<>"",W85<>""),IF(B85<D85,"Invalid","Valid"),"Not applicable") -> Invalid | Y85: Delivered | Z85: =IF(AND(Y85="Cancelled",W85<>""),"Invalid","Valid") -> Valid | AA85: Yes | AB85: Size Issue | AC85: =IF(AA85="Yes", IF(OR(AB85="", AB85="Not Applicable"), "Missing Reason", "Valid"), "Not Applicable") -> Valid | AD85: 45651 | AE85: =IF(AND(W85<>"",AD85<>""),IF(W85<AD85,"Invalid","Valid"),"Not Applicable") -> Invalid | AF85: Processed
A86: UT-100175 | B86: 45610 | C86: CUST_10174 | D86: New | E86: ACCWVNOS | F86: Accessories | G86: Woven Bag | H86: 1599 | I86: =IF(OR(H86<=0,H86>50000),"Outlier","Normal") -> Normal | J86: 1 | K86: =IF(J86>10,"Outlier","Normal") -> Normal | L86: 1599 | M86: =H86*J86*(1-(P86/100)) -> 1599 | N86: =IF(ABS(L86-M86)<1,"Match","Mismatch") -> Match | O86: No code | P86: 0 | Q86: =IF(OR(P86<0,C86>100),"Invalid","valid") -> Invalid | R86: Wallet | S86: Website | T86: Chennai | U86: Tamil Nadu | V86: Bangalore | W86: 45623 | X86: =IF(AND(B86<>"",W86<>""),IF(B86<D86,"Invalid","Valid"),"Not applicable") -> Invalid | Y86: Delivered | Z86: =IF(AND(Y86="Cancelled",W86<>""),"Invalid","Valid") -> Valid | AA86: Yes | AB86: Damaged in Transit | AC86: =IF(AA86="Yes", IF(OR(AB86="", AB86="Not Applicable"), "Missing Reason", "Valid"), "Not Applicable") -> Valid | AD86: 45652 | AE86: =IF(AND(W86<>"",AD86<>""),IF(W86<AD86,"Invalid","Valid"),"Not Applicable") -> Invalid | AF86: Processed
A87: UT-100169 | B87: 45608 | C87: CUST_10168 | D87: New | E87: OUTTWDM | F87: Outerwear | G87: Tweed Jacket | H87: 5599 | I87: =IF(OR(H87<=0,H87>50000),"Outlier","Normal") -> Normal | J87: 1 | K87: =IF(J87>10,"Outlier","Normal") -> Normal | L87: 5599 | M87: =H87*J87*(1-(P87/100)) -> 5599 | N87: =IF(ABS(L87-M87)<1,"Match","Mismatch") -> Match | O87: No code | P87: 0 | Q87: =IF(OR(P87<0,C87>100),"Invalid","valid") -> Invalid | R87: Credit Card | S87: Website | T87: Vadodara | U87: Gujarat | V87: Mumbai | W87: 45623 | X87: =IF(AND(B87<>"",W87<>""),IF(B87<D87,"Invalid","Valid"),"Not applicable") -> Invalid | Y87: Delivered | Z87: =IF(AND(Y87="Cancelled",W87<>""),"Invalid","Valid") -> Valid | AA87: Yes | AB87: Changed Mind | AC87: =IF(AA87="Yes", IF(OR(AB87="", AB87="Not Applicable"), "Missing Reason", "Valid"), "Not Applicable") -> Valid | AD87: 45652 | AE87: =IF(AND(W87<>"",AD87<>""),IF(W87<AD87,"Invalid","Valid"),"Not Applicable") -> Invalid | AF87: Processed
A88: UT-100180 | B88: 45611 | C88: CUST_10179 | D88: New | E88: ACCMTLOS | F88: Accessories | G88: Metal Belt | H88: 899 | I88: =IF(OR(H88<=0,H88>50000),"Outlier","Normal") -> Normal | J88: 1 | K88: =IF(J88>10,"Outlier","Normal") -> Normal | L88: 899 | M88: =H88*J88*(1-(P88/100)) -> 899 | N88: =IF(ABS(L88-M88)<1,"Match","Mismatch") -> Match | O88: No code | P88: 0 | Q88: =IF(OR(P88<0,C88>100),"Invalid","valid") -> Invalid | R88: COD | S88: Instagram Shop | T88: Lucknow | U88: Uttar Pradesh | V88: Delhi | W88: 45624 | X88: =IF(AND(B88<>"",W88<>""),IF(B88<D88,"Invalid","Valid"),"Not applicable") -> Invalid | Y88: Delivered | Z88: =IF(AND(Y88="Cancelled",W88<>""),"Invalid","Valid") -> Valid | AA88: Yes | AB88: Changed Mind | AC88: =IF(AA88="Yes", IF(OR(AB88="", AB88="Not Applicable"), "Missing Reason", "Valid"), "Not Applicable") -> Valid | AD88: 45653 | AE88: =IF(AND(W88<>"",AD88<>""),IF(W88<AD88,"Invalid","Valid"),"Not Applicable") -> Invalid | AF88: Processed
A89: UT-100177 | B89: 45610 | C89: CUST_10176 | D89: New | E89: DRSCROS | F89: Dresses | G89: Crochet Dress | H89: 3199 | I89: =IF(OR(H89<=0,H89>50000),"Outlier","Normal") -> Normal | J89: 1 | K89: =IF(J89>10,"Outlier","Normal") -> Normal | L89: 3199 | M89: =H89*J89*(1-(P89/100)) -> 2719.15 | N89: =IF(ABS(L89-M89)<1,"Match","Mismatch") -> Mismatch | O89: 42309 | P89: 15 | Q89: =IF(OR(P89<0,C89>100),"Invalid","valid") -> Invalid | R89: Debit Card | S89: Instagram Shop | T89: Pune | U89: Maharashtra | V89: Mumbai | W89: 45625 | X89: =IF(AND(B89<>"",W89<>""),IF(B89<D89,"Invalid","Valid"),"Not applicable") -> Invalid | Y89: Delivered | Z89: =IF(AND(Y89="Cancelled",W89<>""),"Invalid","Valid") -> Valid | AA89: Yes | AB89: Size Issue | AC89: =IF(AA89="Yes", IF(OR(AB89="", AB89="Not Applicable"), "Missing Reason", "Valid"), "Not Applicable") -> Valid | AD89: 45654 | AE89: =IF(AND(W89<>"",AD89<>""),IF(W89<AD89,"Invalid","Valid"),"Not Applicable") -> Invalid | AF89: Processed
A90: UT-100227 | B90: 45627 | C90: CUST_10226 | D90: New | E90: OUTCOTM | F90: Outerwear | G90: Puffer Coat | H90: 6499 | I90: =IF(OR(H90<=0,H90>50000),"Outlier","Normal") -> Normal | J90: 1 | K90: =IF(J90>10,"Outlier","Normal") -> Normal | L90: 6499 | M90: =H90*J90*(1-(P90/100)) -> 5199.2 | N90: =IF(ABS(L90-M90)<1,"Match","Mismatch") -> Mismatch | O90: 44166 | P90: 20 | Q90: =IF(OR(P90<0,C90>100),"Invalid","valid") -> Invalid | R90: COD | S90: Mobile App | T90: Delhi | U90: Delhi | V90: Delhi | W90: 45634 | X90: =IF(AND(B90<>"",W90<>""),IF(B90<D90,"Invalid","Valid"),"Not applicable") -> Invalid | Y90: Delivered | Z90: =IF(AND(Y90="Cancelled",W90<>""),"Invalid","Valid") -> Valid | AA90: Yes | AB90: Changed Mind | AC90: =IF(AA90="Yes", IF(OR(AB90="", AB90="Not Applicable"), "Missing Reason", "Valid"), "Not Applicable") -> Valid | AD90: 45654 | AE90: =IF(AND(W90<>"",AD90<>""),IF(W90<AD90,"Invalid","Valid"),"Not Applicable") -> Invalid | AF90: Pending
A91: UT-100179 | B91: 45611 | C91: CUST_10178 | D91: New | E91: OUTHRNL | F91: Outerwear | G91: Herringbone Coat | H91: 6999 | I91: =IF(OR(H91<=0,H91>50000),"Outlier","Normal") -> Normal | J91: 1 | K91: =IF(J91>10,"Outlier","Normal") -> Normal | L91: 6999 | M91: =H91*J91*(1-(P91/100)) -> 6999 | N91: =IF(ABS(L91-M91)<1,"Match","Mismatch") -> Match | O91: No code | P91: 0 | Q91: =IF(OR(P91<0,C91>100),"Invalid","valid") -> Invalid | R91: UPI | S91: Mobile App | T91: Jaipur | U91: Rajasthan | V91: Delhi | W91: 45626 | X91: =IF(AND(B91<>"",W91<>""),IF(B91<D91,"Invalid","Valid"),"Not applicable") -> Invalid | Y91: Delivered | Z91: =IF(AND(Y91="Cancelled",W91<>""),"Invalid","Valid") -> Valid | AA91: Yes | AB91: Wrong Item | AC91: =IF(AA91="Yes", IF(OR(AB91="", AB91="Not Applicable"), "Missing Reason", "Valid"), "Not Applicable") -> Valid | AD91: 45655 | AE91: =IF(AND(W91<>"",AD91<>""),IF(W91<AD91,"Invalid","Valid"),"Not Applicable") -> Invalid | AF91: Processed
A92: UT-100186 | B92: 45613 | C92: CUST_10185 | D92: New | E92: TOPKNTM | F92: Tops | G92: Knotted Top | H92: 1599 | I92: =IF(OR(H92<=0,H92>50000),"Outlier","Normal") -> Normal | J92: 1 | K92: =IF(J92>10,"Outlier","Normal") -> Normal | L92: 1599 | M92: =H92*J92*(1-(P92/100)) -> 1599 | N92: =IF(ABS(L92-M92)<1,"Match","Mismatch") -> Match | O92: No code | P92: 0 | Q92: =IF(OR(P92<0,C92>100),"Invalid","valid") -> Invalid | R92: Credit Card | S92: Instagram Shop | T92: Gurgaon | U92: Haryana | V92: Delhi | W92: 45627 | X92: =IF(AND(B92<>"",W92<>""),IF(B92<D92,"Invalid","Valid"),"Not applicable") -> Invalid | Y92: Delivered | Z92: =IF(AND(Y92="Cancelled",W92<>""),"Invalid","Valid") -> Valid | AA92: Yes | AB92: Damaged in Transit | AC92: =IF(AA92="Yes", IF(OR(AB92="", AB92="Not Applicable"), "Missing Reason", "Valid"), "Not Applicable") -> Valid | AD92: 45655 | AE92: =IF(AND(W92<>"",AD92<>""),IF(W92<AD92,"Invalid","Valid"),"Not Applicable") -> Invalid | AF92: Processed
A93: UT-100229 | B93: 45627 | C93: CUST_10228 | D93: New | E93: DRSPLTM | F93: Dresses | G93: Pleated Dress | H93: 2899 | I93: =IF(OR(H93<=0,H93>50000),"Outlier","Normal") -> Normal | J93: 1 | K93: =IF(J93>10,"Outlier","Normal") -> Normal | L93: 2899 | M93: =H93*J93*(1-(P93/100)) -> 2319.2 | N93: =IF(ABS(L93-M93)<1,"Match","Mismatch") -> Mismatch | O93: 44166 | P93: 20 | Q93: =IF(OR(P93<0,C93>100),"Invalid","valid") -> Invalid | R93: Debit Card | S93: Website | T93: Amritsar | U93: Punjab | V93: Delhi | W93: 45635 | X93: =IF(AND(B93<>"",W93<>""),IF(B93<D93,"Invalid","Valid"),"Not applicable") -> Invalid | Y93: Delivered | Z93: =IF(AND(Y93="Cancelled",W93<>""),"Invalid","Valid") -> Valid | AA93: Yes | AB93: Size Issue | AC93: =IF(AA93="Yes", IF(OR(AB93="", AB93="Not Applicable"), "Missing Reason", "Valid"), "Not Applicable") -> Valid | AD93: 45656 | AE93: =IF(AND(W93<>"",AD93<>""),IF(W93<AD93,"Invalid","Valid"),"Not Applicable") -> Invalid | AF93: Processed
A94: UT-100188 | B94: 45614 | C94: CUST_10187 | D94: Returning | E94: BOTGLTS | F94: Bottoms | G94: Glitter Pants | H94: 2299 | I94: =IF(OR(H94<=0,H94>50000),"Outlier","Normal") -> Normal | J94: 1 | K94: =IF(J94>10,"Outlier","Normal") -> Normal | L94: 2299 | M94: =H94*J94*(1-(P94/100)) -> 2299 | N94: =IF(ABS(L94-M94)<1,"Match","Mismatch") -> Match | O94: No code | P94: 0 | Q94: =IF(OR(P94<0,C94>100),"Invalid","valid") -> Invalid | R94: UPI | S94: Mobile App | T94: Surat | U94: Gujarat | V94: Mumbai | W94: 45627 | X94: =IF(AND(B94<>"",W94<>""),IF(B94<D94,"Invalid","Valid"),"Not applicable") -> Invalid | Y94: Delivered | Z94: =IF(AND(Y94="Cancelled",W94<>""),"Invalid","Valid") -> Valid | AA94: Yes | AB94: Size Issue | AC94: =IF(AA94="Yes", IF(OR(AB94="", AB94="Not Applicable"), "Missing Reason", "Valid"), "Not Applicable") -> Valid | AD94: 45656 | AE94: =IF(AND(W94<>"",AD94<>""),IF(W94<AD94,"Invalid","Valid"),"Not Applicable") -> Invalid | AF94: Processed
A95: UT-100182 | B95: 45612 | C95: CUST_10181 | D95: New | E95: DRSTRFM | F95: Dresses | G95: Tiered Ruffle Dress | H95: 2999 | I95: =IF(OR(H95<=0,H95>50000),"Outlier","Normal") -> Normal | J95: 1 | K95: =IF(J95>10,"Outlier","Normal") -> Normal | L95: 2999 | M95: =H95*J95*(1-(P95/100)) -> 2999 | N95: =IF(ABS(L95-M95)<1,"Match","Mismatch") -> Match | O95: No code | P95: 0 | Q95: =IF(OR(P95<0,C95>100),"Invalid","valid") -> Invalid | R95: Debit Card | S95: Mobile App | T95: Mumbai | U95: Maharashtra | V95: Mumbai | W95: 45627 | X95: =IF(AND(B95<>"",W95<>""),IF(B95<D95,"Invalid","Valid"),"Not applicable") -> Invalid | Y95: Delivered | Z95: =IF(AND(Y95="Cancelled",W95<>""),"Invalid","Valid") -> Valid | AA95: Yes | AB95: Quality Defect | AC95: =IF(AA95="Yes", IF(OR(AB95="", AB95="Not Applicable"), "Missing Reason", "Valid"), "Not Applicable") -> Valid | AD95: 45656 | AE95: =IF(AND(W95<>"",AD95<>""),IF(W95<AD95,"Invalid","Valid"),"Not Applicable") -> Invalid | AF95: Processed
A96: UT-100184 | B96: 45613 | C96: CUST_10183 | D96: New | E96: OUTCMLM | F96: Outerwear | G96: Camel Coat | H96: 7499 | I96: =IF(OR(H96<=0,H96>50000),"Outlier","Normal") -> Normal | J96: 1 | K96: =IF(J96>10,"Outlier","Normal") -> Normal | L96: 7499 | M96: =H96*J96*(1-(P96/100)) -> 7499 | N96: =IF(ABS(L96-M96)<1,"Match","Mismatch") -> Match | O96: No code | P96: 0 | Q96: =IF(OR(P96<0,C96>100),"Invalid","valid") -> Invalid | R96: UPI | S96: Website | T96: Chandigarh | U96: Punjab | V96: Delhi | W96: 45628 | X96: =IF(AND(B96<>"",W96<>""),IF(B96<D96,"Invalid","Valid"),"Not applicable") -> Invalid | Y96: Delivered | Z96: =IF(AND(Y96="Cancelled",W96<>""),"Invalid","Valid") -> Valid | AA96: Yes | AB96: Size Issue | AC96: =IF(AA96="Yes", IF(OR(AB96="", AB96="Not Applicable"), "Missing Reason", "Valid"), "Not Applicable") -> Valid | AD96: 45657 | AE96: =IF(AND(W96<>"",AD96<>""),IF(W96<AD96,"Invalid","Valid"),"Not Applicable") -> Invalid | AF96: Processed
A97: UT-100189 | B97: 45614 | C97: CUST_10188 | D97: New | E97: OUTFXFM | F97: Outerwear | G97: Faux Fur Jacket | H97: 5999 | I97: =IF(OR(H97<=0,H97>50000),"Outlier","Normal") -> Normal | J97: 1 | K97: =IF(J97>10,"Outlier","Normal") -> Normal | L97: 5999 | M97: =H97*J97*(1-(P97/100)) -> 5099.15 | N97: =IF(ABS(L97-M97)<1,"Match","Mismatch") -> Mismatch | O97: 42309 | P97: 15 | Q97: =IF(OR(P97<0,C97>100),"Invalid","valid") -> Invalid | R97: Debit Card | S97: Instagram Shop | T97: Patna | U97: Bihar | V97: Delhi | W97: 45630 | X97: =IF(AND(B97<>"",W97<>""),IF(B97<D97,"Invalid","Valid"),"Not applicable") -> Invalid | Y97: Delivered | Z97: =IF(AND(Y97="Cancelled",W97<>""),"Invalid","Valid") -> Valid | AA97: Yes | AB97: Wrong Item | AC97: =IF(AA97="Yes", IF(OR(AB97="", AB97="Not Applicable"), "Missing Reason", "Valid"), "Not Applicable") -> Valid | AD97: 45659 | AE97: =IF(AND(W97<>"",AD97<>""),IF(W97<AD97,"Invalid","Valid"),"Not Applicable") -> Invalid | AF97: Processed
A98: UT-100232 | B98: 45628 | C98: CUST_10231 | D98: New | E98: OUTWNDL | F98: Outerwear | G98: Windbreaker | H98: 3299 | I98: =IF(OR(H98<=0,H98>50000),"Outlier","Normal") -> Normal | J98: 1 | K98: =IF(J98>10,"Outlier","Normal") -> Normal | L98: 3299 | M98: =H98*J98*(1-(P98/100)) -> 3299 | N98: =IF(ABS(L98-M98)<1,"Match","Mismatch") -> Match | O98: No code | P98: 0 | Q98: =IF(OR(P98<0,C98>100),"Invalid","valid") -> Invalid | R98: UPI | S98: Website | T98: Srinagar | U98: Jammu & Kashmir | V98: Delhi | W98: 45637 | X98: =IF(AND(B98<>"",W98<>""),IF(B98<D98,"Invalid","Valid"),"Not applicable") -> Invalid | Y98: Delivered | Z98: =IF(AND(Y98="Cancelled",W98<>""),"Invalid","Valid") -> Valid | AA98: Yes | AB98: Wrong Item | AC98: =IF(AA98="Yes", IF(OR(AB98="", AB98="Not Applicable"), "Missing Reason", "Valid"), "Not Applicable") -> Valid | AD98: 45659 | AE98: =IF(AND(W98<>"",AD98<>""),IF(W98<AD98,"Invalid","Valid"),"Not Applicable") -> Invalid | AF98: Pending
A99: UT-100234 | B99: 45629 | C99: CUST_10233 | D99: New | E99: TOPSWTS | F99: Tops | G99: Cropped Sweater | H99: 2199 | I99: =IF(OR(H99<=0,H99>50000),"Outlier","Normal") -> Normal | J99: 1 | K99: =IF(J99>10,"Outlier","Normal") -> Normal | L99: 2199 | M99: =H99*J99*(1-(P99/100)) -> 2199 | N99: =IF(ABS(L99-M99)<1,"Match","Mismatch") -> Match | O99: No code | P99: 0 | Q99: =IF(OR(P99<0,C99>100),"Invalid","valid") -> Invalid | R99: Debit Card | S99: Instagram Shop | T99: Darjeeling | U99: West Bengal | V99: Delhi | W99: 45638 | X99: =IF(AND(B99<>"",W99<>""),IF(B99<D99,"Invalid","Valid"),"Not applicable") -> Invalid | Y99: Delivered | Z99: =IF(AND(Y99="Cancelled",W99<>""),"Invalid","Valid") -> Valid | AA99: Yes | AB99: Size Issue | AC99: =IF(AA99="Yes", IF(OR(AB99="", AB99="Not Applicable"), "Missing Reason", "Valid"), "Not Applicable") -> Valid | AD99: 45660 | AE99: =IF(AND(W99<>"",AD99<>""),IF(W99<AD99,"Invalid","Valid"),"Not Applicable") -> Invalid | AF99: Processed
A100: UT-100196 | B100: 45617 | C100: CUST_10195 | D100: New | E100: TOPMTLS | F100: Tops | G100: Metallic Top | H100: 1999 | I100: =IF(OR(H100<=0,H100>50000),"Outlier","Normal") -> Normal | J100: 1 | K100: =IF(J100>10,"Outlier","Normal") -> Normal | L100: 1999 | M100: =H100*J100*(1-(P100/100)) -> 1999 | N100: =IF(ABS(L100-M100)<1,"Match","Mismatch") -> Match | O100: No code | P100: 0 | Q100: =IF(OR(P100<0,C100>100),"Invalid","valid") -> Invalid | R100: UPI | S100: Website | T100: Mysore | U100: Karnataka | V100: Bangalore | W100: 45631 | X100: =IF(AND(B100<>"",W100<>""),IF(B100<D100,"Invalid","Valid"),"Not applicable") -> Invalid | Y100: Delivered | Z100: =IF(AND(Y100="Cancelled",W100<>""),"Invalid","Valid") -> Valid | AA100: Yes | AB100: Size Issue | AC100: =IF(AA100="Yes", IF(OR(AB100="", AB100="Not Applicable"), "Missing Reason", "Valid"), "Not Applicable") -> Valid | AD100: 45660 | AE100: =IF(AND(W100<>"",AD100<>""),IF(W100<AD100,"Invalid","Valid"),"Not Applicable") -> Invalid | AF100: Processed
A101: UT-100192 | B101: 45615 | C101: CUST_10191 | D101: New | E101: DRSVLRS | F101: Dresses | G101: Velour Dress | H101: 2999 | I101: =IF(OR(H101<=0,H101>50000),"Outlier","Normal") -> Normal | J101: 1 | K101: =IF(J101>10,"Outlier","Normal") -> Normal | L101: 2999 | M101: =H101*J101*(1-(P101/100)) -> 2999 | N101: =IF(ABS(L101-M101)<1,"Match","Mismatch") -> Match | O101: No code | P101: 0 | Q101: =IF(OR(P101<0,C101>100),"Invalid","valid") -> Invalid | R101: UPI | S101: Instagram Shop | T101: Coimbatore | U101: Tamil Nadu | V101: Bangalore | W101: 45631 | X101: =IF(AND(B101<>"",W101<>""),IF(B101<D101,"Invalid","Valid"),"Not applicable") -> Invalid | Y101: Delivered | Z101: =IF(AND(Y101="Cancelled",W101<>""),"Invalid","Valid") -> Valid | AA101: Yes | AB101: Changed Mind | AC101: =IF(AA101="Yes", IF(OR(AB101="", AB101="Not Applicable"), "Missing Reason", "Valid"), "Not Applicable") -> Valid | AD101: 45660 | AE101: =IF(AND(W101<>"",AD101<>""),IF(W101<AD101,"Invalid","Valid"),"Not Applicable") -> Invalid | AF101: Processed
A102: UT-100203 | B102: 45619 | C102: CUST_10202 | D102: Returning | E102: BOTORGM | F102: Bottoms | G102: Organza Pants | H102: 2399 | I102: =IF(OR(H102<=0,H102>50000),"Outlier","Normal") -> Normal | J102: 1 | K102: =IF(J102>10,"Outlier","Normal") -> Normal | L102: 2399 | M102: =H102*J102*(1-(P102/100)) -> 2399 | N102: =IF(ABS(L102-M102)<1,"Match","Mismatch") -> Match | O102: No code | P102: 0 | Q102: =IF(OR(P102<0,C102>100),"Invalid","valid") -> Invalid | R102: COD | S102: Mobile App | T102: Chennai | U102: Tamil Nadu | V102: Bangalore | W102: 45633 | X102: =IF(AND(B102<>"",W102<>""),IF(B102<D102,"Invalid","Valid"),"Not applicable") -> Invalid | Y102: Delivered | Z102: =IF(AND(Y102="Cancelled",W102<>""),"Invalid","Valid") -> Valid | AA102: Yes | AB102: Quality Defect | AC102: =IF(AA102="Yes", IF(OR(AB102="", AB102="Not Applicable"), "Missing Reason", "Valid"), "Not Applicable") -> Valid | AD102: 45661 | AE102: =IF(AND(W102<>"",AD102<>""),IF(W102<AD102,"Invalid","Valid"),"Not Applicable") -> Invalid | AF102: Processed
...

Sheet Validation_Summary
A1: Rule ID | B1: Validation Check | C1: Expected Outcome | D1: Status (Valid / Invalid / Not Applicable) | E1: Notes
A2: V1 | B2: rder_id follows UT-XXXXXX | C2: 100% compliance | D2: =IF(AND(LEFT(urbanthreads_q4!A2,3)="UT",LEN(urbanthreads_q4!A2)=9,ISNUMBER(--MID(urbanthreads_q4!A2,4,6))),"Valid","Invalid") -> Invalid | E2: Correct order_id format (UT-XXXXXX)
A3: V2 | B3: customer_type contains only "New" or "Returning" | C3: No other values | D3: =IF(OR(urbanthreads_q4!B2="New",urbanthreads_q4!B2="Returning"),"Valid","Invalid") -> Invalid | E3: Replace invalid customer_type values with New/Returning
A4: V3 | B4: quantity is a positive integer | C4: No zeros, negatives, or decimals | D4: =IF(ISNUMBER(urbanthreads_q4!C2),IF(AND(urbanthreads_q4!C2>0,MOD(urbanthreads_q4!C2,1)=0),"Valid","Invalid"),"Invalid") -> Invalid | E4: Remove negative/zero/decimal quantities
A5: V4 | B5: discount_percent between 0–100 | C5: No out-of-range values | D5: =IF(AND(urbanthreads_q4!D2>=0,urbanthreads_q4!D2<=100),"Valid","Invalid") -> Invalid | E5: Adjust discount_percent to 0–100
A6: V5 | B6: order_date falls within Q4 2024 (Oct 1 – Dec 31) | C6: No dates outside range | D6: =IF(AND(urbanthreads_q4!E2>=DATE(2024,10,1),urbanthreads_q4!E2<=DATE(2024,12,31)),"Valid","Invalid") -> Invalid | E6: Fix order_dates outside Q4 2024
A7: V6 | B7: payment_method matches one of 5 defined options | C7: No undefined methods | D7: =IF(OR(urbanthreads_q4!F2="Credit Card",urbanthreads_q4!F2="Debit Card",urbanthreads_q4!F2="Net Banking",urbanthreads_q4!F2="UPI",urbanthreads_q4!F2="COD"),"Valid","Invalid") -> Invalid | E7: Correct payment_method to one of the 5 valid options
A8: V7 | B8: If delivery_status = "Delivered", delivery_date must exist | C8: Cross-field consistency | D8: =IF(urbanthreads_q4!G2="Delivered",IF(urbanthreads_q4!H2<>"","Valid","Invalid"),"Not Applicable") -> Not Applicable | E8: Add delivery_date for Delivered orders
A9: V8 | B9: If return_initiated = "No", return_reason must be blank | C9: Business logic compliance | D9: =IF(urbanthreads_q4!I2="No",IF(urbanthreads_q4!J2="","Valid","Invalid"),"Not Applicable") -> Not Applicable | E9: Remove return_reason if return_initiated = No
A10: V9 | B10: warehouse_origin is Mumbai, Delhi, or Bangalore | C10: No other warehouses | D10: =IF(urbanthreads_q4!I2="No",IF(urbanthreads_q4!J2="","Valid","Invalid"),"Not Applicable") -> Not Applicable | E10: Correct warehouse_origin to Mumbai, Delhi, or Bangalore
A11: V10 | B11: refund_status = "Not Applicable" when return_initiated = "No" | C11: Logical consistency | D11: =IF(urbanthreads_q4!I2="No",IF(urbanthreads_q4!L2="Not Applicable","Valid","Invalid"),"Not Applicable") -> Not Applicable | E11: Set refund_status = Not Applicable if return_initiated = No
A12: CF1 | B12: delivery_status = RTO → return_initiated = No | C12: Cross-field consistency | D12: =IF(urbanthreads_q4!G2="RTO",IF(urbanthreads_q4!I2="No","Valid","Invalid"),"Not Applicable") -> Not Applicable | E12: Set return_initiated = No if delivery_status = RTO
A13: CF2 | B13: customer_type = New → customer_id not repeated | C13: Business logic validation | D13: =IF(AND(urbanthreads_q4!B2="New",COUNTIFS(urbanthreads_q4!B:B,"New",urbanthreads_q4!N:N,urbanthreads_q4!N2)>1),"Invalid","Valid") -> Valid | E13: Remove duplicate New customer_ids
A14: BL1 | B14: delivery_time = delivery_date – order_date | C14: Flag negatives or >30 days | D14: =IF(AND(ISNUMBER(urbanthreads_q4!E2),ISNUMBER(urbanthreads_q4!H2)), IF(OR(urbanthreads_q4!H2-urbanthreads_q4!E2<0,urbanthreads_q4!H2-urbanthreads_q4!E2>30), "Invalid", "Valid"), "Not Applicable") -> Not Applicable | E14: Check delivery_date/order_date errors
A15: BL2 | B15: return window = return_received – delivery_date | C15: Flag >30 days | D15: =IF(AND(urbanthreads_q4!P2<>"",urbanthreads_q4!H2<>"",urbanthreads_q4!P2-urbanthreads_q4!H2>30),"Invalid","Valid") -> Valid | E15: Ensure return_received ≤ 30 days after delivery_date
